Traceback (most recent call last):
  File "/Users/kvarada/opt/miniconda3/lib/python3.10/site-packages/jupyter_cache/executors/utils.py", line 51, in single_nb_execution
    executenb(
  File "/Users/kvarada/opt/miniconda3/lib/python3.10/site-packages/nbclient/client.py", line 1204, in execute
    return NotebookClient(nb=nb, resources=resources, km=km, **kwargs).execute()
  File "/Users/kvarada/opt/miniconda3/lib/python3.10/site-packages/nbclient/util.py", line 84, in wrapped
    return just_run(coro(*args, **kwargs))
  File "/Users/kvarada/opt/miniconda3/lib/python3.10/site-packages/nbclient/util.py", line 62, in just_run
    return loop.run_until_complete(coro)
  File "/Users/kvarada/opt/miniconda3/lib/python3.10/asyncio/base_events.py", line 646, in run_until_complete
    return future.result()
  File "/Users/kvarada/opt/miniconda3/lib/python3.10/site-packages/nbclient/client.py", line 663, in async_execute
    await self.async_execute_cell(
  File "/Users/kvarada/opt/miniconda3/lib/python3.10/site-packages/nbclient/client.py", line 965, in async_execute_cell
    await self._check_raise_for_error(cell, cell_index, exec_reply)
  File "/Users/kvarada/opt/miniconda3/lib/python3.10/site-packages/nbclient/client.py", line 862, in _check_raise_for_error
    raise CellExecutionError.from_cell_and_msg(cell, exec_reply_content)
nbclient.exceptions.CellExecutionError: An error occurred while executing the following cell:
------------------
make_num_tree_plot_reg(
     preprocessor, X_train, y_train, X_test, y_test, [1, 5, 10, 25, 50, 100, 200, 500]
)
------------------

[0;31m---------------------------------------------------------------------------[0m
[0;31mNameError[0m                                 Traceback (most recent call last)
Cell [0;32mIn [26], line 1[0m
[0;32m----> 1[0m [43mmake_num_tree_plot_reg[49m(
[1;32m      2[0m      preprocessor, X_train, y_train, X_test, y_test, [[38;5;241m1[39m, [38;5;241m5[39m, [38;5;241m10[39m, [38;5;241m25[39m, [38;5;241m50[39m, [38;5;241m100[39m, [38;5;241m200[39m, [38;5;241m500[39m]
[1;32m      3[0m )

[0;31mNameError[0m: name 'make_num_tree_plot_reg' is not defined
NameError: name 'make_num_tree_plot_reg' is not defined

